<?xml version="1.0" ?>
<!-- =================================================================================== -->
<!-- |    This document was autogenerated by xacro from kaku.xacro                     | -->
<!-- |    EDITING THIS FILE BY HAND IS NOT RECOMMENDED                                 | -->
<!-- =================================================================================== -->
<robot name="kaku" xmlns:xacro="http://www.ros.org/wiki/xacro">
  <material name="Gold">
    <color rgba="1 0.87 0 1.0"/>
  </material>
  <material name="Wood">
    <color rgba="0.87 0.72 0.53 1.0"/>
    <!-- <color rgba="0.52 0.40 0.24 1.0"/> -->
  </material>
  <material name="Wood_dark">
    <color rgba="0.87 0.72 0.53 1.0"/>
    <!-- <color rgba="0.52 0.40 0.24 1.0"/> -->
  </material>
  <material name="Blue">
    <color rgba="0 0 1 1.0"/>
  </material>
  <link name="car_base">
    <visual>
      <origin rpy="0 0 0" xyz="0 0 0.065"/>
      <geometry>
        <mesh filename="package://sis_arm_description/urdf/model/meshes/car_base.stl" scale="0.001 0.001 0.001"/>
      </geometry>
      <material name="Wood"/>
    </visual>
  </link>
  <link name="caster">
    <visual>
      <origin rpy="0 0 3.14" xyz="-0.07 0 0.033"/>
      <geometry>
        <mesh filename="package://sis_arm_description/urdf/model/meshes/me212_robot_wheel.stl" scale="0.001 0.001 0.001"/>
        <!-- <mesh filename="package://sis_arm_description/urdf/model/meshes/me212_robot_wheel.stl"/> -->
      </geometry>
      <material name="Black"/>
    </visual>
  </link>
  <joint name="caster_hinge" type="fixed">
    <!-- <axis xyz="0 1 0"/> -->
    <parent link="car_base"/>
    <child link="caster"/>
    <!-- <origin xyz="0.01 0.048 0.03" rpy="0 0 0"/> -->
  </joint>
  <link name="left_wheel">
    <visual>
      <origin rpy="0 0 0" xyz="0 0 0"/>
      <geometry>
        <mesh filename="package://sis_arm_description/urdf/model/meshes/left_wheel.dae"/>
      </geometry>
      <material name="Blue"/>
    </visual>
  </link>
  <link name="right_wheel">
    <visual>
      <origin rpy="0 0 0" xyz="0 0 0"/>
      <geometry>
        <mesh filename="package://sis_arm_description/urdf/model/meshes/right_wheel.dae"/>
      </geometry>
      <material name="Blue"/>
    </visual>
  </link>
  <joint name="left_wheel_hinge" type="revolute">
    <axis xyz="0 1 0"/>
    <limit effort="8.0" lower="-100000" upper="100000" velocity="10"/>
    <parent link="car_base"/>
    <child link="left_wheel"/>
    <origin rpy="0 0 0" xyz="0.035 0.09 0.03"/>
  </joint>
  <joint name="right_wheel_hinge" type="revolute">
    <axis xyz="0 1 0"/>
    <limit effort="8.0" lower="-100000" upper="100000" velocity="10"/>
    <parent link="car_base"/>
    <child link="right_wheel"/>
    <origin rpy="0 0 0" xyz=" 0.035 -0.09 0.03"/>
  </joint>

  <link name="sticker_base">
    <visual>
      <origin rpy="0 0 0" xyz="0 0 -0.044"/>
      <geometry>
        <box size=".005 .005 .088"/>
      </geometry>
      <material name="Gold"/>
    </visual>
  </link>
  <joint name="sticker_base_hinge" type="fixed">
    <parent link="camera_mount"/>
    <child link="sticker_base"/>
    <origin rpy=" 0 0 0" xyz="0 0.09 0"/>
  </joint>
  <link name="sticker_base_1">
    <visual>
      <origin rpy="0 0 0" xyz="0 0 -0.044"/>
      <geometry>
        <box size=".005 .005 .088"/>
      </geometry>
      <material name="Gold"/>
    </visual>
  </link>
  <joint name="sticker_base_1_hinge" type="fixed">
    <parent link="camera_mount"/>
    <child link="sticker_base_1"/>
    <origin rpy=" 0 0 0" xyz="0 -0.09 0"/>
  </joint>
  <link name="sticker_base_2">
    <visual>
      <origin rpy="0 0 0" xyz="0 0 -0.044"/>
      <geometry>
        <box size=".005 .005 .088"/>
      </geometry>
      <material name="Gold"/>
    </visual>
  </link>
  <joint name="sticker_base_2_hinge" type="fixed">
    <parent link="camera_mount"/>
    <child link="sticker_base_2"/>
    <origin rpy=" 0 0 0" xyz="0.073 0.09 0"/>
  </joint>
  <link name="sticker_base_3">
    <visual>
      <origin rpy="0 0 0" xyz="0 0 -0.044"/>
      <geometry>
        <box size=".005 .005 .088"/>
      </geometry>
      <material name="Gold"/>
    </visual>
  </link>
  <joint name="sticker_base_3_hinge" type="fixed">
    <parent link="camera_mount"/>
    <child link="sticker_base_3"/>
    <origin rpy=" 0 0 0" xyz="0.073 -0.09 0"/>
  </joint>
  <link name="camera_mount">
    <visual>
      <origin rpy="0 0 0" xyz="0 0 0"/>
      <geometry>
        <mesh filename="package://sis_arm_description/urdf/model/meshes/car_level.stl" scale="0.001 0.001 0.001"/>
      </geometry>
      <material name="Wood_dark"/>
    </visual>
  </link>
  <joint name="camera_mount_hinge" type="fixed">
    <!-- <axis xyz="0 1 0"/> -->
    <parent link="car_base"/>
    <child link="camera_mount"/>
    <origin rpy="0 0 0" xyz="-0.097 0 0.163"/>
  </joint>

  <link name="sticker">
    <collision>
      <origin rpy="0 0 0" xyz="0.0 0.0 0.305"/>
      <geometry>
        <box size="0.02 0.02 0.45"/>
      </geometry>
    </collision>

    <visual>
      <origin rpy="0 0 0" xyz="-0.01 -0.03 0.08"/>
      <geometry>
        <mesh filename="package://sis_arm_description/urdf/model/meshes/20_item.dae"/>
      </geometry>
    </visual>
  </link>
  <joint name="sticker_hinge" type="fixed">
    <parent link="car_base"/>
    <child link="sticker"/>
    <origin rpy=" 0 0 0" xyz="-0.037 0 0"/>
  </joint>

  <link name="sr300">
    <visual>
      <origin rpy="0 0 1.57" xyz="0 0 -0.02"/>
      <geometry>
        <mesh filename="package://sis_arm_description/urdf/model/meshes/realsense.stl" scale="0.001 0.001 0.001"/>
      </geometry>
      <material name="White"/>
    </visual>
  </link>
  <joint name="sr300_hinge" type="fixed">
    <!-- <axis xyz="0 1 0"/> -->
    <parent link="sticker"/>
    <child link="sr300"/>
    <origin rpy="0 0 -1.57" xyz="0 0 0.52"/>
  </joint>
  <link name="pi_camera">
    <visual>
      <origin rpy="0 0 0" xyz="0 0 0"/>
      <geometry>
        <mesh filename="package://sis_arm_description/urdf/model/meshes/CameraPanTiltAssy.stl" scale="0.0009 0.0009 0.0009"/>
      </geometry>
      <material name="White"/>
    </visual>
  </link>
  <joint name="pi_camera_hinge" type="fixed">
    <axis xyz="0 1 0"/>
    <parent link="sticker"/>
    <child link="pi_camera"/>
    <origin rpy="0 0 0" xyz="0.018 0 0.37"/>
  </joint>
  <joint name="arm_to_car" type="fixed">
    <!-- <axis xyz="0 1 0"/> -->
    <parent link="car_base"/>
    <child link="base_link"/>
    <origin rpy="0 0 0" xyz="0.085 0 0.068"/>
  </joint>
  <!-- Included URDF Files -->
  <material name="White">
    <color rgba="0.87 0.90 0.87 1.0"/>
  </material>
  <material name="Black">
    <color rgba="0.08 0.08 0.08 1.0"/>
  </material>
  <material name="Gray">
    <color rgba="0.2 0.2 0.21 1.0"/>
  </material>
  <material name="Green">
    <color rgba="0.22 0.32 0.14 1.0"/>
  </material>
  <!-- As we don't have here a turtlebot base, add a base_link link as its location reference -->
  <link name="base_link"/>
  <link name="arm_base_link"/>
  <joint name="arm_base_joint" type="fixed">
    <origin xyz="0 0 0.019"/>
    <parent link="base_link"/>
    <child link="arm_base_link"/>
  </joint>
  <!-- fake gripper_link joint gives us a free servo!
         this makes us 5DOF and saves you $44.90
         that's a lot of coin! -->
  <link name="gripper_link"/>
  <joint name="gripper_link_joint" type="revolute">
    <origin rpy="0 -1.57 0" xyz="0 0 0.112"/>
    <parent link="arm_wrist_flex_link"/>
    <child link="gripper_link"/>
    <limit effort="30" lower="-3.14" upper="3.14" velocity="1"/>
    <axis xyz="1 0 0"/>
  </joint>
  <joint name="arm_shoulder_pan_servo_joint" type="fixed">
    <origin rpy="1.570795 0 1.570795" xyz="0 0 0"/>
    <parent link="arm_base_link"/>
    <child link="arm_shoulder_pan_servo_link"/>
  </joint>
  <link name="arm_shoulder_pan_servo_link">
    <inertial>
      <mass value="0.055"/>
      <origin xyz="0 0 0"/>
      <inertia ixx="0.000017012" ixy="0.0" ixz="0.0" iyy="0.000013258" iyz="0.0" izz="0.000009483"/>
    </inertial>
    <visual>
      <origin rpy="0 0 0" xyz=" 0 0 0 "/>
      <geometry>
        <mesh filename="package://sis_arm_description/meshes/ax12_box.stl" scale="0.001 0.001 0.001"/>
      </geometry>
      <material name="Black"/>
    </visual>
    <collision>
      <origin rpy="0 0 0" xyz="0.0 0.0 -0.01241"/>
      <geometry>
        <box size="0.025 0.038 0.04762"/>
      </geometry>
    </collision>
  </link>
  <gazebo reference="arm_shoulder_pan_servo_link">
    <material>Gazebo/Black</material>
    <selfCollide>true</selfCollide>
    <gravity>true</gravity>
  </gazebo>
  <joint name="arm_shoulder_pan_joint" type="revolute">
    <origin rpy="-1.570795 1.570795 3.14159" xyz="0 0.019 0"/>
    <axis xyz="0 0 -1"/>
    <limit effort="30" lower="-2.617" upper="2.617" velocity="1.571"/>
    <dynamics friction="0.13"/>
    <parent link="arm_shoulder_pan_servo_link"/>
    <child link="arm_shoulder_pan_link"/>
  </joint>
  <link name="arm_shoulder_pan_link">
    <inertial>
      <mass value="0.008"/>
      <origin xyz="0 0 0"/>
      <inertia ixx="0.000001" ixy="0.0" ixz="0.0" iyy="0.000001" iyz="0.0" izz="0.000001"/>
    </inertial>
    <visual>
      <origin rpy="0 0 0" xyz=" 0 0 0 "/>
      <geometry>
        <mesh filename="package://sis_arm_description/meshes/F3.stl" scale="0.001 0.001 0.001"/>
      </geometry>
      <material name="White"/>
    </visual>
    <collision>
      <origin rpy="0 0 0" xyz="0.0 0.0 -0.0045"/>
      <geometry>
        <box size="0.025 0.038 0.009"/>
      </geometry>
    </collision>
  </link>
  <gazebo reference="arm_shoulder_pan_link">
    <material>Gazebo/White</material>
    <selfCollide>true</selfCollide>
    <gravity>true</gravity>
  </gazebo>
  <joint name="arm_shoulder_lift_servo_joint" type="fixed">
    <origin rpy="0 3.14159 0" xyz="0 0 -0.0415"/>
    <parent link="arm_shoulder_pan_link"/>
    <child link="arm_shoulder_lift_servo_link"/>
  </joint>
  <link name="arm_shoulder_lift_servo_link">
    <inertial>
      <mass value="0.055"/>
      <origin xyz="0 0 0"/>
      <inertia ixx="0.000017012" ixy="0.0" ixz="0.0" iyy="0.000013258" iyz="0.0" izz="0.000009483"/>
    </inertial>
    <visual>
      <origin rpy="0 0 0" xyz=" 0 0 0 "/>
      <geometry>
        <mesh filename="package://sis_arm_description/meshes/ax12_box.stl" scale="0.001 0.001 0.001"/>
      </geometry>
      <material name="Black"/>
    </visual>
    <collision>
      <origin rpy="0 0 0" xyz="0.0 0.0 -0.01241"/>
      <geometry>
        <box size="0.025 0.038 0.04762"/>
      </geometry>
    </collision>
  </link>
  <gazebo reference="arm_shoulder_lift_servo_link">
    <material>Gazebo/Black</material>
    <selfCollide>true</selfCollide>
    <gravity>true</gravity>
  </gazebo>
  <joint name="arm_shoulder_lift_joint" type="revolute">
    <origin rpy="0 0 0" xyz="0 0 0"/>
    <axis xyz="0 1 0"/>
    <limit effort="30" lower="-2.2" upper="2.16" velocity="1.571"/>
    <dynamics friction="0.13"/>
    <parent link="arm_shoulder_lift_servo_link"/>
    <child link="arm_shoulder_lift_link"/>
  </joint>
  <link name="arm_shoulder_lift_link">
    <inertial>
      <mass value="0.016"/>
      <origin xyz="0 0 0"/>
      <inertia ixx="0.000001" ixy="0.0" ixz="0.0" iyy="0.000001" iyz="0.0" izz="0.000001"/>
    </inertial>
    <visual>
      <origin rpy="0 0 0" xyz=" 0 0 0 "/>
      <geometry>
        <mesh filename="package://sis_arm_description/meshes/F4.stl" scale="0.001 0.001 0.001"/>
      </geometry>
      <material name="White"/>
    </visual>
    <collision>
      <origin rpy="0 0 0" xyz="0.0 0.0 0.0215"/>
      <geometry>
        <box size="0.028 0.0485 0.065"/>
      </geometry>
    </collision>
  </link>
  <gazebo reference="arm_shoulder_lift_link">
    <material>Gazebo/White</material>
    <selfCollide>true</selfCollide>
    <gravity>true</gravity>
  </gazebo>
  <joint name="arm_shoulder_F3_0_joint" type="fixed">
    <origin rpy="0 3.14159 0" xyz="0 0 0.0545"/>
    <parent link="arm_shoulder_lift_link"/>
    <child link="arm_shoulder_F3_0_link"/>
  </joint>
  <link name="arm_shoulder_F3_0_link">
    <inertial>
      <mass value="0.005"/>
      <origin xyz="0 0 0"/>
      <inertia ixx="0.000001" ixy="0.0" ixz="0.0" iyy="0.000001" iyz="0.0" izz="0.000001"/>
    </inertial>
    <visual>
      <origin rpy="0 0 0" xyz=" 0 0 0 "/>
      <geometry>
        <mesh filename="package://sis_arm_description/meshes/F3.stl" scale="0.001 0.001 0.001"/>
      </geometry>
      <material name="White"/>
    </visual>
    <collision>
      <origin rpy="0 0 0" xyz="0.0 0.0 -0.0045"/>
      <geometry>
        <box size="0.025 0.038 0.009"/>
      </geometry>
    </collision>
  </link>
  <gazebo reference="arm_shoulder_F3_0_link">
    <material>Gazebo/White</material>
    <selfCollide>true</selfCollide>
    <gravity>true</gravity>
  </gazebo>
  <joint name="arm_elbow_flex_servo_joint" type="fixed">
    <origin rpy="0 3.14159 0" xyz="0 0 -0.0415"/>
    <parent link="arm_shoulder_F3_0_link"/>
    <child link="arm_elbow_flex_servo_link"/>
  </joint>
  <link name="arm_elbow_flex_servo_link">
    <inertial>
      <mass value="0.055"/>
      <origin xyz="0 0 0"/>
      <inertia ixx="0.000017012" ixy="0.0" ixz="0.0" iyy="0.000013258" iyz="0.0" izz="0.000009483"/>
    </inertial>
    <visual>
      <origin rpy="0 0 0" xyz=" 0 0 0 "/>
      <geometry>
        <mesh filename="package://sis_arm_description/meshes/ax12_box.stl" scale="0.001 0.001 0.001"/>
      </geometry>
      <material name="Black"/>
    </visual>
    <collision>
      <origin rpy="0 0 0" xyz="0.0 0.0 -0.01241"/>
      <geometry>
        <box size="0.025 0.038 0.04762"/>
      </geometry>
    </collision>
  </link>
  <gazebo reference="arm_elbow_flex_servo_link">
    <material>Gazebo/Black</material>
    <selfCollide>true</selfCollide>
    <gravity>true</gravity>
  </gazebo>
  <joint name="arm_elbow_flex_joint" type="revolute">
    <origin rpy="0 0 0" xyz="0 0 0"/>
    <axis xyz="0 1 0"/>
    <limit effort="30" lower="-2.42" upper="2.38" velocity="1.571"/>
    <dynamics friction="0.13"/>
    <parent link="arm_elbow_flex_servo_link"/>
    <child link="arm_elbow_flex_link"/>
  </joint>
  <link name="arm_elbow_flex_link">
    <inertial>
      <mass value="0.016"/>
      <origin xyz="0 0 0"/>
      <inertia ixx="0.000001" ixy="0.0" ixz="0.0" iyy="0.000001" iyz="0.0" izz="0.000001"/>
    </inertial>
    <visual>
      <origin rpy="0 0 0" xyz=" 0 0 0 "/>
      <geometry>
        <mesh filename="package://sis_arm_description/meshes/F4.stl" scale="0.001 0.001 0.001"/>
      </geometry>
      <material name="White"/>
    </visual>
    <collision>
      <origin rpy="0 0 0" xyz="0.0 0.0 0.0215"/>
      <geometry>
        <box size="0.028 0.0485 0.065"/>
      </geometry>
    </collision>
  </link>
  <gazebo reference="arm_elbow_flex_link">
    <material>Gazebo/White</material>
    <selfCollide>true</selfCollide>
    <gravity>true</gravity>
  </gazebo>
  <joint name="arm_elbow_F3_0_joint" type="fixed">
    <origin rpy="0 3.14159 0" xyz="0 0 0.0545"/>
    <parent link="arm_elbow_flex_link"/>
    <child link="arm_elbow_F3_0_link"/>
  </joint>
  <link name="arm_elbow_F3_0_link">
    <inertial>
      <mass value="0.005"/>
      <origin xyz="0 0 0"/>
      <inertia ixx="0.000001" ixy="0.0" ixz="0.0" iyy="0.000001" iyz="0.0" izz="0.000001"/>
    </inertial>
    <visual>
      <origin rpy="0 0 0" xyz=" 0 0 0 "/>
      <geometry>
        <mesh filename="package://sis_arm_description/meshes/F3.stl" scale="0.001 0.001 0.001"/>
      </geometry>
      <material name="White"/>
    </visual>
    <collision>
      <origin rpy="0 0 0" xyz="0.0 0.0 -0.0045"/>
      <geometry>
        <box size="0.025 0.038 0.009"/>
      </geometry>
    </collision>
  </link>
  <gazebo reference="arm_elbow_F3_0_link">
    <material>Gazebo/White</material>
    <selfCollide>true</selfCollide>
    <gravity>true</gravity>
  </gazebo>
  <joint name="arm_wrist_flex_servo_joint" type="fixed">
    <origin rpy="0 3.14159 0" xyz="0 0 -0.0415"/>
    <parent link="arm_elbow_F3_0_link"/>
    <child link="arm_wrist_flex_servo_link"/>
  </joint>
  <link name="arm_wrist_flex_servo_link">
    <inertial>
      <mass value="0.055"/>
      <origin xyz="0 0 0"/>
      <inertia ixx="0.000017012" ixy="0.0" ixz="0.0" iyy="0.000013258" iyz="0.0" izz="0.000009483"/>
    </inertial>
    <visual>
      <origin rpy="0 0 0" xyz=" 0 0 0 "/>
      <geometry>
        <mesh filename="package://sis_arm_description/meshes/ax12_box.stl" scale="0.001 0.001 0.001"/>
      </geometry>
      <material name="Black"/>
    </visual>
    <collision>
      <origin rpy="0 0 0" xyz="0.0 0.0 -0.01241"/>
      <geometry>
        <box size="0.025 0.038 0.04762"/>
      </geometry>
    </collision>
  </link>
  <gazebo reference="arm_wrist_flex_servo_link">
    <material>Gazebo/Black</material>
    <selfCollide>true</selfCollide>
    <gravity>true</gravity>
  </gazebo>
  <joint name="arm_wrist_flex_joint" type="revolute">
    <origin rpy="0 0 0" xyz="0 0 0"/>
    <axis xyz="0 1 0"/>
    <limit effort="30" lower="-1.72" upper="1.68" velocity="1.571"/>
    <dynamics friction="0.13"/>
    <parent link="arm_wrist_flex_servo_link"/>
    <child link="arm_wrist_flex_link"/>
  </joint>
  <link name="arm_wrist_flex_link">
    <inertial>
      <mass value="0.010"/>
      <origin xyz="0 0 0"/>
      <inertia ixx="0.000001" ixy="0.0" ixz="0.0" iyy="0.000001" iyz="0.0" izz="0.000001"/>
    </inertial>
    <visual>
      <origin rpy="0 0 0" xyz=" 0 0 0 "/>
      <geometry>
        <mesh filename="package://sis_arm_description/meshes/F2.stl" scale="0.001 0.001 0.001"/>
      </geometry>
      <material name="White"/>
    </visual>
    <collision>
      <origin rpy="0 0 0" xyz="0.0 0.0 0.00775"/>
      <geometry>
        <box size="0.025 0.0485 0.0375"/>
      </geometry>
    </collision>
  </link>
  <gazebo reference="arm_wrist_flex_link">
    <material>Gazebo/White</material>
    <selfCollide>true</selfCollide>
    <gravity>true</gravity>
  </gazebo>
  <joint name="arm_wrist_F3_0_joint" type="fixed">
    <origin rpy="0 3.14159 -3.14159" xyz="0 0 0.0265"/>
    <parent link="arm_wrist_flex_link"/>
    <child link="arm_wrist_F3_0_link"/>
  </joint>
  <link name="arm_wrist_F3_0_link">
    <inertial>
      <mass value="0.005"/>
      <origin xyz="0 0 0"/>
      <inertia ixx="0.000001" ixy="0.0" ixz="0.0" iyy="0.000001" iyz="0.0" izz="0.000001"/>
    </inertial>
    <visual>
      <origin rpy="0 0 0" xyz=" 0 0 0 "/>
      <geometry>
        <mesh filename="package://sis_arm_description/meshes/F3.stl" scale="0.001 0.001 0.001"/>
      </geometry>
      <material name="White"/>
    </visual>
    <collision>
      <origin rpy="0 0 0" xyz="0.0 0.0 -0.0045"/>
      <geometry>
        <box size="0.025 0.038 0.009"/>
      </geometry>
    </collision>
  </link>
  <gazebo reference="arm_wrist_F3_0_link">
    <material>Gazebo/White</material>
    <selfCollide>true</selfCollide>
    <gravity>true</gravity>
  </gazebo>
  <joint name="gripper_servo_joint" type="fixed">
    <origin rpy="1.570795 3.14159 1.570795" xyz="0 0 -0.019"/>
    <parent link="arm_wrist_F3_0_link"/>
    <child link="gripper_servo_link"/>
  </joint>
  <link name="gripper_servo_link">
    <inertial>
      <mass value="0.055"/>
      <origin xyz="0 0 0"/>
      <inertia ixx="0.000017012" ixy="0.0" ixz="0.0" iyy="0.000013258" iyz="0.0" izz="0.000009483"/>
    </inertial>
    <visual>
      <origin rpy="0 0 0" xyz=" 0 0 0 "/>
      <geometry>
        <mesh filename="package://sis_arm_description/meshes/ax12_box.stl" scale="0.001 0.001 0.001"/>
      </geometry>
      <material name="Black"/>
    </visual>
    <collision>
      <origin rpy="0 0 0" xyz="0.0 0.0 -0.01241"/>
      <geometry>
        <box size="0.025 0.038 0.04762"/>
      </geometry>
    </collision>
  </link>
  <gazebo reference="gripper_servo_link">
    <material>Gazebo/Black</material>
    <selfCollide>true</selfCollide>
    <gravity>true</gravity>
  </gazebo>
  <joint name="gripper_finger_base_joint" type="fixed">
    <origin rpy="1.570795 -3.14159 1.570795" xyz="0.01  0.038 0"/>
    <parent link="gripper_servo_link"/>
    <child link="gripper_finger_base_link"/>
  </joint>
  <link name="gripper_finger_base_link">
    <inertial>
      <mass value="0.00001"/>
      <origin xyz="0 0 0"/>
      <inertia ixx="1.0" ixy="0.0" ixz="0.0" iyy="1.0" iyz="0.0" izz="1.0"/>
    </inertial>
    <visual>
      <origin rpy="3.14159 -1.570795 1.570795" xyz="0.016 0 -.015 "/>
      <geometry>
        <mesh filename="package://sis_arm_description/meshes/pincher_finger_base.stl" scale=".01 .01 .01"/>
      </geometry>
      <material name="White"/>
    </visual>
    <collision>
      <origin rpy="0 0 0" xyz="0.015 0 -0.0135"/>
      <geometry>
        <box size="0.002 0.040 0.075"/>
      </geometry>
    </collision>
  </link>
  <gazebo reference="gripper_finger_base_link">
    <material>Gazebo/White</material>
    <selfCollide>true</selfCollide>
    <gravity>true</gravity>
  </gazebo>
  <!-- Finger 1 -->
  <joint name="gripper_joint" type="prismatic">
    <origin rpy="0 0 0" xyz="0 0 0"/>
    <axis xyz="1 0 0"/>
    <limit effort="30" lower="0.002" upper="0.031" velocity="0.5"/>
    <parent link="gripper_servo_link"/>
    <child link="gripper_active_link"/>
  </joint>
  <link name="gripper_active_link">
    <inertial>
      <mass value="0.00001"/>
      <origin xyz="0 0 0"/>
      <inertia ixx="1.0" ixy="0.0" ixz="0.0" iyy="1.0" iyz="0.0" izz="1.0"/>
    </inertial>
    <visual>
      <origin rpy="-1.570795 0 0" xyz="-0.02 0.023 0"/>
      <geometry>
        <mesh filename="package://sis_arm_description/meshes/pincher_finger.stl" scale=".01 .01 .01"/>
      </geometry>
      <material name="White"/>
    </visual>
    <collision>
      <origin rpy="-1.570795 0 0" xyz="-0.02 0.023 0"/>
      <geometry>
        <box size="0.036 0.028 0.004"/>
      </geometry>
    </collision>
  </link>
  <gazebo reference="gripper_active_link">
    <material>Gazebo/White</material>
    <selfCollide>true</selfCollide>
    <gravity>true</gravity>
  </gazebo>
  <!-- Finger 2 -->
  <!-- Note: currently static but should be a Mimic of Finger 1 -->
  <joint name="gripper2_joint" type="fixed">
    <parent link="gripper_servo_link"/>
    <child link="gripper_active2_link"/>
  </joint>
  <link name="gripper_active2_link">
    <inertial>
      <mass value="0.00001"/>
      <origin xyz="0 0 0"/>
      <inertia ixx="1.0" ixy="0.0" ixz="0.0" iyy="1.0" iyz="0.0" izz="1.0"/>
    </inertial>
    <visual>
      <origin rpy="-1.570795 3.14159 0" xyz="-0.02 0.023 0"/>
      <geometry>
        <mesh filename="package://sis_arm_description/meshes/pincher_finger.stl" scale=".01 .01 .01"/>
      </geometry>
      <material name="White"/>
    </visual>
    <collision>
      <origin rpy="-1.570795 3.14159 0" xyz="-0.02 0.023 0"/>
      <geometry>
        <box size="0.036 0.028 0.004"/>
      </geometry>
    </collision>
  </link>
  <gazebo reference="gripper_active2_link">
    <material>Gazebo/White</material>
    <selfCollide>true</selfCollide>
    <gravity>true</gravity>
  </gazebo>
  <!-- Using Mimic -->
  <!-- gripper 2 joint -->
  <!--  ### Mimic would be better but causes Missing Joint error in Moveit 
      <joint name="gripper2_joint" type="prismatic">
      <origin xyz="0 0 0" rpy="0 0 0"/>
      <axis xyz="0 0 1"/>
      <limit effort="30" velocity="0.5" lower="0.002" upper="0.031"/>
      <parent link="gripper_servo_link"/>
      <child link="gripper_active2_link"/>
      <mimic joint="gripper_joint" multiplier="-.5"  offset = "0"/>
    </joint-->
</robot>

